Workbook

Sheet BASE_DE_DATOS
A1: FECHA COMPLETA | B1: MES | C1: MUNICIPIO | D1: POBLADO | E1: folio CIIA | F1: HORA DE SALIDA | G1: KM INICIAL / Km de Salida | H1: RECORRIDO | I1: HORA DE LLEGADA | J1: KM FINAL / Km de Llegada | K1: GASTO COMBUSTI | L1: Gasolina de Salida | M1: Gasolina de Llegada | N1: Dotación de Gasolina(LLENAR GASTO DE COMBUSTIBLE) | O1: Oficio Numero | P1: Oficio Fecha | Q1: observaciones | R1: Usuario Responsable | S1: Áreas de Adscripción | T1: Tipo de Vehículo | U1: Placas | V1: No. De Licencia
A2: 24/06/2026 | B2: =UPPER(TEXT(A2, "MMMM")) -> JUNIO | C2: TOLUCA | D2: ZINACANTEPEC-(REPRESENTACIÓN)PENSIÓN | F2: 09:00 | G2: 23379 | H2: 100 | I2: 19:00 | J2: =G2+H2 -> 23479 | K2: =IF(N2="","",N2) -> 200 | L2: 1/4 | M2: 1/4 | N2: 200 | R2: VÍCTOR LEONARDO OLMEDO GONZALEZ | S2: RESIDENCIA NAUCALPAN | T2: NISSAN VERSA | U2: MGX-543-A | V2: 0101P3402484l
A3: 25/06/2026 | B3: =UPPER(TEXT(A3, "MMMM")) -> JUNIO | C3: HUEHUETOCA | D3: HUEHUETOCA - SANTIAGO TLALTEPOXCO | F3: 09:00 | G3: =J2 -> 23479 | H3: 0 | I3: 19:00 | J3: =G3+H3 -> 23479 | K3: =IF(N3="","",N3) -> 300 | L3: 1/2 | M3: 1/4 | N3: 300 | R3: VÍCTOR LEONARDO OLMEDO GONZALEZ | S3: RESIDENCIA NAUCALPAN | T3: NISSAN VERSA | U3: MGX-543-A | V3: 0101P3402484l
A4: 26/06/2026 | B4: =UPPER(TEXT(A4, "MMMM")) -> JUNIO | C4: TULTITLAN-NICOLAS ROMERO | D4: SAN FRANCISCO MAGÚ | F4: 09:00 | G4: =J3 -> 23479 | H4: 120 | I4: 19:00 | J4: =G4+H4 -> 23599 | K4: =IF(N4="","",N4) -> 300 | L4: 1/4 | M4: 1/4 | N4: 300 | R4: VÍCTOR LEONARDO OLMEDO GONZALEZ | S4: RESIDENCIA NAUCALPAN | T4: NISSAN VERSA | U4: MGX-543-A | V4: 0101P3402484l
A5: 29/06/2026 | B5: =UPPER(TEXT(A5, "MMMM")) -> JUNIO | C5: TOLUCA | D5: ZINACANTEPEC-(REPRESENTACIÓN)PENSIÓN | F5: 09:00 | G5: =J4 -> 23599 | H5: 200 | I5: 19:00 | J5: =G5+H5 -> 23799 | K5: =IF(N5="","",N5) -> 200 | L5: 1/4 | M5: 1/4 | N5: 200 | R5: VÍCTOR LEONARDO OLMEDO GONZALEZ | S5: RESIDENCIA NAUCALPAN | T5: NISSAN VERSA | U5: MGX-543-A | V5: 0101P3402484l
A6: 30/06/2026 | B6: =UPPER(TEXT(A6, "MMMM")) -> JUNIO | C6: TULTITLAN | F6: 09:00 | G6: =J5 -> 23799 | H6: 50 | I6: 19:00 | J6: =G6+H6 -> 23849 | K6: =IF(N6="","",N6) -> 200 | L6: 1/4 | M6: 1/4 | N6: 200 | R6: VÍCTOR LEONARDO OLMEDO GONZALEZ | S6: RESIDENCIA NAUCALPAN | T6: NISSAN VERSA | U6: MGX-543-A | V6: 0101P3402484l
A7: 46305 | B7: =UPPER(TEXT(A7, "MMMM")) -> OCTUBRE | C7: ZITACUARO | F7: 09:00 | G7: =J6 -> 23849 | I7: 19:00 | J7: =G7+H7 -> 23849 | K7: =IF(N7="","",N7) | R7: VÍCTOR LEONARDO OLMEDO GONZALEZ | S7: RESIDENCIA NAUCALPAN | T7: NISSAN VERSA | U7: MGX-543-A | V7: 0101P3402484l
A8: 07/07/2026 | B8: =UPPER(TEXT(A8, "MMMM")) -> JULIO | F8: 09:00 | G8: =J7 -> 23849 | I8: 19:00 | J8: =G8+H8 -> 23849 | K8: =IF(N8="","",N8) | R8: VÍCTOR LEONARDO OLMEDO GONZALEZ | S8: RESIDENCIA NAUCALPAN | T8: NISSAN VERSA | U8: MGX-543-A | V8: 0101P3402484l
A9: 08/07/2026 | B9: =UPPER(TEXT(A9, "MMMM")) -> JULIO | F9: 09:00 | G9: =J8 -> 23849 | I9: 19:00 | J9: =G9+H9 -> 23849 | K9: =IF(N9="","",N9) | R9: VÍCTOR LEONARDO OLMEDO GONZALEZ | S9: RESIDENCIA NAUCALPAN | T9: NISSAN VERSA | U9: MGX-543-A | V9: 0101P3402484l
A10: 09/07/2026 | B10: =UPPER(TEXT(A10, "MMMM")) -> JULIO | F10: 09:00 | G10: =J9 -> 23849 | I10: 19:00 | J10: =G10+H10 -> 23849 | K10: =IF(N10="","",N10) | R10: VÍCTOR LEONARDO OLMEDO GONZALEZ | S10: RESIDENCIA NAUCALPAN | T10: NISSAN VERSA | U10: MGX-543-A | V10: 0101P3402484l
A11: 10/07/2026 | B11: =UPPER(TEXT(A11, "MMMM")) -> JULIO | F11: 09:00 | G11: =J10 -> 23849 | I11: 19:00 | J11: =G11+H11 -> 23849 | K11: =IF(N11="","",N11) | R11: VÍCTOR LEONARDO OLMEDO GONZALEZ | S11: RESIDENCIA NAUCALPAN | T11: NISSAN VERSA | U11: MGX-543-A | V11: 0101P3402484l
A12: 11/07/2026 | B12: =UPPER(TEXT(A12, "MMMM")) -> JULIO | F12: 09:00 | G12: =J11 -> 23849 | I12: 19:00 | J12: =G12+H12 -> 23849 | K12: =IF(N12="","",N12) | R12: VÍCTOR LEONARDO OLMEDO GONZALEZ | S12: RESIDENCIA NAUCALPAN | T12: NISSAN VERSA | U12: MGX-543-A | V12: 0101P3402484l
A13: 12/07/2026 | B13: =UPPER(TEXT(A13, "MMMM")) -> JULIO | F13: 09:00 | G13: =J12 -> 23849 | I13: 19:00 | J13: =G13+H13 -> 23849 | K13: =IF(N13="","",N13) | R13: VÍCTOR LEONARDO OLMEDO GONZALEZ | S13: RESIDENCIA NAUCALPAN | T13: NISSAN VERSA | U13: MGX-543-A | V13: 0101P3402484l
A14: 13/07/2026 | B14: =UPPER(TEXT(A14, "MMMM")) -> JULIO | F14: 09:00 | G14: =J13 -> 23849 | I14: 19:00 | J14: =G14+H14 -> 23849 | K14: =IF(N14="","",N14) | R14: VÍCTOR LEONARDO OLMEDO GONZALEZ | S14: RESIDENCIA NAUCALPAN | T14: NISSAN VERSA | U14: MGX-543-A | V14: 0101P3402484l
A15: 14/07/2026 | B15: =UPPER(TEXT(A15, "MMMM")) -> JULIO | F15: 09:00 | G15: =J14 -> 23849 | I15: 19:00 | J15: =G15+H15 -> 23849 | K15: =IF(N15="","",N15) | R15: VÍCTOR LEONARDO OLMEDO GONZALEZ | S15: RESIDENCIA NAUCALPAN | T15: NISSAN VERSA | U15: MGX-543-A | V15: 0101P3402484l
A16: 15/07/2026 | B16: =UPPER(TEXT(A16, "MMMM")) -> JULIO | F16: 09:00 | G16: =J15 -> 23849 | I16: 19:00 | J16: =G16+H16 -> 23849 | K16: =IF(N16="","",N16) | R16: VÍCTOR LEONARDO OLMEDO GONZALEZ | S16: RESIDENCIA NAUCALPAN | T16: NISSAN VERSA | U16: MGX-543-A | V16: 0101P3402484l
A17: 16/07/2026 | B17: =UPPER(TEXT(A17, "MMMM")) -> JULIO | F17: 09:00 | G17: =J16 -> 23849 | I17: 19:00 | J17: =G17+H17 -> 23849 | K17: =IF(N17="","",N17) | R17: VÍCTOR LEONARDO OLMEDO GONZALEZ | S17: RESIDENCIA NAUCALPAN | T17: NISSAN VERSA | U17: MGX-543-A | V17: 0101P3402484l
A18: 17/07/2026 | B18: =UPPER(TEXT(A18, "MMMM")) -> JULIO | F18: 09:00 | G18: =J17 -> 23849 | I18: 19:00 | J18: =G18+H18 -> 23849 | K18: =IF(N18="","",N18) | R18: VÍCTOR LEONARDO OLMEDO GONZALEZ | S18: RESIDENCIA NAUCALPAN | T18: NISSAN VERSA | U18: MGX-543-A | V18: 0101P3402484l
A19: 18/07/2026 | B19: =UPPER(TEXT(A19, "MMMM")) -> JULIO | F19: 09:00 | G19: =J18 -> 23849 | I19: 19:00 | J19: =G19+H19 -> 23849 | K19: =IF(N19="","",N19) | R19: VÍCTOR LEONARDO OLMEDO GONZALEZ | S19: RESIDENCIA NAUCALPAN | T19: NISSAN VERSA | U19: MGX-543-A | V19: 0101P3402484l
... A32: 31/07/2026 | B32: =UPPER(TEXT(A32, "MMMM")) -> JULIO | F32: 09:00 | G32: =J31 -> 23849 | I32: 19:00 | J32: =G32+H32 -> 23849 | K32: =IF(N32="","",N32) | R32: VÍCTOR LEONARDO OLMEDO GONZALEZ | S32: RESIDENCIA NAUCALPAN | T32: NISSAN VERSA | U32: MGX-543-A | V32: 0101P3402484l
K33: =IF(N33="","",N33)
K34: =IF(N34="","",N34)
K35: =IF(N35="","",N35)
K36: =IF(N36="","",N36)
K37: =IF(N37="","",N37)
K38: =IF(N38="","",N38)
K39: =IF(N39="","",N39)
K40: =IF(N40="","",N40)
K41: =IF(N41="","",N41)
K42: =IF(N42="","",N42)
K43: =IF(N43="","",N43)
K44: =IF(N44="","",N44)
... K49: =IF(N49="","",N49)

Sheet 1_RECORRIDO_Y_CONSUMO
A1: Marca: | B1: NISSAN | C1: No. Serie: | D1: 3N1CN8AE2RL860265 | E1: Resguardante: | F1: VÍCTOR LEONARDO OLMEDO GONZALEZ
A2: Tipo: | B2: VERSA | C2: No. Inventario: | E2: Mes: | F2: JUNIO
A3: Modelo: | B3: 2024 | C3: Rendimiento: | D3: 12 | E3: km Inicial: | F3: 23,378.00
A4: Placas: | B4: MGX-543-A | C4: Adscripcion: | D4: RESIDENCIA NAUCALPAN
A6: FECHA | B6: MUNICIPIO | C6: POBLADO | D6: folio CIIA | E6: KM INICIAL | F6: RECORRIDO | G6: KM FINAL | H6: GASTO COMBUSTI | J6: TABLA DE CALCULO GASTO DE OMBUSTIBLE (NO SE IMPRIME)
A7: =IF(BASE_DE_DATOS!A2="","",BASE_DE_DATOS!A2) -> 24/06/2026 | B7: =IF(BASE_DE_DATOS!C2="","",BASE_DE_DATOS!C2) -> TOLUCA | C7: =IF(BASE_DE_DATOS!D2="","",BASE_DE_DATOS!D2) -> ZINACANTEPEC-(REPRESENTACIÓN)PENSIÓN | D7: =IF(BASE_DE_DATOS!E2="","",BASE_DE_DATOS!E2) | E7: =IF(BASE_DE_DATOS!G2="","",BASE_DE_DATOS!G2) -> 23379 | F7: =IF(BASE_DE_DATOS!H2="","",BASE_DE_DATOS!H2) -> 100 | G7: =IF(BASE_DE_DATOS!J2="","",BASE_DE_DATOS!J2) -> 23479 | H7: =IF(BASE_DE_DATOS!N2="","",BASE_DE_DATOS!N2) -> 200
A8: =IF(BASE_DE_DATOS!A3="","",BASE_DE_DATOS!A3) -> 25/06/2026 | B8: =IF(BASE_DE_DATOS!C3="","",BASE_DE_DATOS!C3) -> HUEHUETOCA | C8: =IF(BASE_DE_DATOS!D3="","",BASE_DE_DATOS!D3) -> HUEHUETOCA - SANTIAGO TLALTEPOXCO | D8: =IF(BASE_DE_DATOS!E3="","",BASE_DE_DATOS!E3) | E8: =IF(BASE_DE_DATOS!G3="","",BASE_DE_DATOS!G3) -> 23479 | F8: =IF(BASE_DE_DATOS!H3="","",BASE_DE_DATOS!H3) -> 0 | G8: =IF(BASE_DE_DATOS!J3="","",BASE_DE_DATOS!J3) -> 23479 | H8: =IF(BASE_DE_DATOS!N3="","",BASE_DE_DATOS!N3) -> 300 | J8: RENDIMIENTO SIRMAS | K8: KM RECORRIDO | L8: PU COMBUSTIBLE | M8: LITROS COMBUSTIBLE | N8: GASTO COMBUSTIBLE
A9: =IF(BASE_DE_DATOS!A4="","",BASE_DE_DATOS!A4) -> 26/06/2026 | B9: =IF(BASE_DE_DATOS!C4="","",BASE_DE_DATOS!C4) -> TULTITLAN-NICOLAS ROMERO | C9: =IF(BASE_DE_DATOS!D4="","",BASE_DE_DATOS!D4) -> SAN FRANCISCO MAGÚ | D9: =IF(BASE_DE_DATOS!E4="","",BASE_DE_DATOS!E4) | E9: =IF(BASE_DE_DATOS!G4="","",BASE_DE_DATOS!G4) -> 23479 | F9: =IF(BASE_DE_DATOS!H4="","",BASE_DE_DATOS!H4) -> 120 | G9: =IF(BASE_DE_DATOS!J4="","",BASE_DE_DATOS!J4) -> 23599 | H9: =IF(BASE_DE_DATOS!N4="","",BASE_DE_DATOS!N4) -> 300
A10: =IF(BASE_DE_DATOS!A5="","",BASE_DE_DATOS!A5) -> 29/06/2026 | B10: =IF(BASE_DE_DATOS!C5="","",BASE_DE_DATOS!C5) -> TOLUCA | C10: =IF(BASE_DE_DATOS!D5="","",BASE_DE_DATOS!D5) -> ZINACANTEPEC-(REPRESENTACIÓN)PENSIÓN | D10: =IF(BASE_DE_DATOS!E5="","",BASE_DE_DATOS!E5) | E10: =IF(BASE_DE_DATOS!G5="","",BASE_DE_DATOS!G5) -> 23599 | F10: =IF(BASE_DE_DATOS!H5="","",BASE_DE_DATOS!H5) -> 200 | G10: =IF(BASE_DE_DATOS!J5="","",BASE_DE_DATOS!J5) -> 23799 | H10: =IF(BASE_DE_DATOS!N5="","",BASE_DE_DATOS!N5) -> 200 | J10: 12 | K10: =F7 -> 100 | L10: 23.99 | M10: =K10/J10 -> 8.3333333 | N10: =L10*M10 -> 199.91667
A11: =IF(BASE_DE_DATOS!A6="","",BASE_DE_DATOS!A6) -> 30/06/2026 | B11: =IF(BASE_DE_DATOS!C6="","",BASE_DE_DATOS!C6) -> TULTITLAN | C11: =IF(BASE_DE_DATOS!D6="","",BASE_DE_DATOS!D6) | D11: =IF(BASE_DE_DATOS!E6="","",BASE_DE_DATOS!E6) | E11: =IF(BASE_DE_DATOS!G6="","",BASE_DE_DATOS!G6) -> 23799 | F11: =IF(BASE_DE_DATOS!H6="","",BASE_DE_DATOS!H6) -> 50 | G11: =IF(BASE_DE_DATOS!J6="","",BASE_DE_DATOS!J6) -> 23849 | H11: =IF(BASE_DE_DATOS!N6="","",BASE_DE_DATOS!N6) -> 200 | J11: 12 | K11: =F8 -> 0 | L11: 23.99 | M11: =K11/J11 -> 0 | N11: =L11*M11 -> 0
A12: =IF(BASE_DE_DATOS!A7="","",BASE_DE_DATOS!A7) -> 46305 | B12: =IF(BASE_DE_DATOS!C7="","",BASE_DE_DATOS!C7) -> ZITACUARO | C12: =IF(BASE_DE_DATOS!D7="","",BASE_DE_DATOS!D7) | D12: =IF(BASE_DE_DATOS!E7="","",BASE_DE_DATOS!E7) | E12: =IF(BASE_DE_DATOS!G7="","",BASE_DE_DATOS!G7) -> 23849 | F12: =IF(BASE_DE_DATOS!H7="","",BASE_DE_DATOS!H7) | G12: =IF(BASE_DE_DATOS!J7="","",BASE_DE_DATOS!J7) -> 23849 | H12: =IF(BASE_DE_DATOS!N7="","",BASE_DE_DATOS!N7) | J12: 12 | K12: =F9 -> 120 | L12: 23.79 | M12: =K12/J12 -> 10 | N12: =L12*M12 -> 237.9
A13: =IF(BASE_DE_DATOS!A8="","",BASE_DE_DATOS!A8) -> 07/07/2026 | B13: =IF(BASE_DE_DATOS!C8="","",BASE_DE_DATOS!C8) | C13: =IF(BASE_DE_DATOS!D8="","",BASE_DE_DATOS!D8) | D13: =IF(BASE_DE_DATOS!E8="","",BASE_DE_DATOS!E8) | E13: =IF(BASE_DE_DATOS!G8="","",BASE_DE_DATOS!G8) -> 23849 | F13: =IF(BASE_DE_DATOS!H8="","",BASE_DE_DATOS!H8) | G13: =IF(BASE_DE_DATOS!J8="","",BASE_DE_DATOS!J8) -> 23849 | H13: =IF(BASE_DE_DATOS!N8="","",BASE_DE_DATOS!N8) | J13: 12 | K13: =F10 -> 200 | L13: 23.27 | M13: =K13/J13 -> 16.666667 | N13: =L13*M13 -> 387.83333
A14: =IF(BASE_DE_DATOS!A9="","",BASE_DE_DATOS!A9) -> 08/07/2026 | B14: =IF(BASE_DE_DATOS!C9="","",BASE_DE_DATOS!C9) | C14: =IF(BASE_DE_DATOS!D9="","",BASE_DE_DATOS!D9) | D14: =IF(BASE_DE_DATOS!E9="","",BASE_DE_DATOS!E9) | E14: =IF(BASE_DE_DATOS!G9="","",BASE_DE_DATOS!G9) -> 23849 | F14: =IF(BASE_DE_DATOS!H9="","",BASE_DE_DATOS!H9) | G14: =IF(BASE_DE_DATOS!J9="","",BASE_DE_DATOS!J9) -> 23849 | H14: =IF(BASE_DE_DATOS!N9="","",BASE_DE_DATOS!N9) | J14: 11.7 | K14: =F11 -> 50 | L14: 23.99 | M14: =K14/J14 -> 4.2735043 | N14: =L14*M14 -> 102.52137
A15: =IF(BASE_DE_DATOS!A10="","",BASE_DE_DATOS!A10) -> 09/07/2026 | B15: =IF(BASE_DE_DATOS!C10="","",BASE_DE_DATOS!C10) | C15: =IF(BASE_DE_DATOS!D10="","",BASE_DE_DATOS!D10) | D15: =IF(BASE_DE_DATOS!E10="","",BASE_DE_DATOS!E10) | E15: =IF(BASE_DE_DATOS!G10="","",BASE_DE_DATOS!G10) -> 23849 | F15: =IF(BASE_DE_DATOS!H10="","",BASE_DE_DATOS!H10) | G15: =IF(BASE_DE_DATOS!J10="","",BASE_DE_DATOS!J10) -> 23849 | H15: =IF(BASE_DE_DATOS!N10="","",BASE_DE_DATOS!N10) | J15: 11.7 | K15: =F12 | L15: 23.99 | M15: =K15/J15 -> #VALUE! | N15: =L15*M15 -> #VALUE!
A16: =IF(BASE_DE_DATOS!A11="","",BASE_DE_DATOS!A11) -> 10/07/2026 | B16: =IF(BASE_DE_DATOS!C11="","",BASE_DE_DATOS!C11) | C16: =IF(BASE_DE_DATOS!D11="","",BASE_DE_DATOS!D11) | D16: =IF(BASE_DE_DATOS!E11="","",BASE_DE_DATOS!E11) | E16: =IF(BASE_DE_DATOS!G11="","",BASE_DE_DATOS!G11) -> 23849 | F16: =IF(BASE_DE_DATOS!H11="","",BASE_DE_DATOS!H11) | G16: =IF(BASE_DE_DATOS!J11="","",BASE_DE_DATOS!J11) -> 23849 | H16: =IF(BASE_DE_DATOS!N11="","",BASE_DE_DATOS!N11) | J16: 11.7 | K16: =F13 | L16: 23.99 | M16: =K16/J16 -> #VALUE! | N16: =L16*M16 -> #VALUE!
A17: =IF(BASE_DE_DATOS!A12="","",BASE_DE_DATOS!A12) -> 11/07/2026 | B17: =IF(BASE_DE_DATOS!C12="","",BASE_DE_DATOS!C12) | C17: =IF(BASE_DE_DATOS!D12="","",BASE_DE_DATOS!D12) | D17: =IF(BASE_DE_DATOS!E12="","",BASE_DE_DATOS!E12) | E17: =IF(BASE_DE_DATOS!G12="","",BASE_DE_DATOS!G12) -> 23849 | F17: =IF(BASE_DE_DATOS!H12="","",BASE_DE_DATOS!H12) | G17: =IF(BASE_DE_DATOS!J12="","",BASE_DE_DATOS!J12) -> 23849 | H17: =IF(BASE_DE_DATOS!N12="","",BASE_DE_DATOS!N12) | J17: 11.7 | K17: =F14 | L17: 23.99 | M17: =K17/J17 -> #VALUE! | N17: =L17*M17 -> #VALUE!
A18: =IF(BASE_DE_DATOS!A13="","",BASE_DE_DATOS!A13) -> 12/07/2026 | B18: =IF(BASE_DE_DATOS!C13="","",BASE_DE_DATOS!C13) | C18: =IF(BASE_DE_DATOS!D13="","",BASE_DE_DATOS!D13) | D18: =IF(BASE_DE_DATOS!E13="","",BASE_DE_DATOS!E13) | E18: =IF(BASE_DE_DATOS!G13="","",BASE_DE_DATOS!G13) -> 23849 | F18: =IF(BASE_DE_DATOS!H13="","",BASE_DE_DATOS!H13) | G18: =IF(BASE_DE_DATOS!J13="","",BASE_DE_DATOS!J13) -> 23849 | H18: =IF(BASE_DE_DATOS!N13="","",BASE_DE_DATOS!N13) | J18: 11.7 | K18: =F15 | L18: 23.99 | M18: =K18/J18 -> #VALUE! | N18: =L18*M18 -> #VALUE!
A19: =IF(BASE_DE_DATOS!A14="","",BASE_DE_DATOS!A14) -> 13/07/2026 | B19: =IF(BASE_DE_DATOS!C14="","",BASE_DE_DATOS!C14) | C19: =IF(BASE_DE_DATOS!D14="","",BASE_DE_DATOS!D14) | D19: =IF(BASE_DE_DATOS!E14="","",BASE_DE_DATOS!E14) | E19: =IF(BASE_DE_DATOS!G14="","",BASE_DE_DATOS!G14) -> 23849 | F19: =IF(BASE_DE_DATOS!H14="","",BASE_DE_DATOS!H14) | G19: =IF(BASE_DE_DATOS!J14="","",BASE_DE_DATOS!J14) -> 23849 | H19: =IF(BASE_DE_DATOS!N14="","",BASE_DE_DATOS!N14) | J19: 11.7 | K19: =F16 | L19: 23.99 | M19: =K19/J19 -> #VALUE! | N19: =L19*M19 -> #VALUE!
A20: =IF(BASE_DE_DATOS!A15="","",BASE_DE_DATOS!A15) -> 14/07/2026 | B20: =IF(BASE_DE_DATOS!C15="","",BASE_DE_DATOS!C15) | C20: =IF(BASE_DE_DATOS!D15="","",BASE_DE_DATOS!D15) | D20: =IF(BASE_DE_DATOS!E15="","",BASE_DE_DATOS!E15) | E20: =IF(BASE_DE_DATOS!G15="","",BASE_DE_DATOS!G15) -> 23849 | F20: =IF(BASE_DE_DATOS!H15="","",BASE_DE_DATOS!H15) | G20: =IF(BASE_DE_DATOS!J15="","",BASE_DE_DATOS!J15) -> 23849 | H20: =IF(BASE_DE_DATOS!N15="","",BASE_DE_DATOS!N15) | J20: 11.7 | K20: =F17 | L20: 23.99 | M20: =K20/J20 -> #VALUE! | N20: =L20*M20 -> #VALUE!
A21: =IF(BASE_DE_DATOS!A16="","",BASE_DE_DATOS!A16) -> 15/07/2026 | B21: =IF(BASE_DE_DATOS!C16="","",BASE_DE_DATOS!C16) | C21: =IF(BASE_DE_DATOS!D16="","",BASE_DE_DATOS!D16) | D21: =IF(BASE_DE_DATOS!E16="","",BASE_DE_DATOS!E16) | E21: =IF(BASE_DE_DATOS!G16="","",BASE_DE_DATOS!G16) -> 23849 | F21: =IF(BASE_DE_DATOS!H16="","",BASE_DE_DATOS!H16) | G21: =IF(BASE_DE_DATOS!J16="","",BASE_DE_DATOS!J16) -> 23849 | H21: =IF(BASE_DE_DATOS!N16="","",BASE_DE_DATOS!N16) | J21: 11.7 | K21: =F18 | L21: 23.99 | M21: =K21/J21 -> #VALUE! | N21: =L21*M21 -> #VALUE!
... A37: =IF(BASE_DE_DATOS!A32="","",BASE_DE_DATOS!A32) -> 31/07/2026 | B37: =IF(BASE_DE_DATOS!C32="","",BASE_DE_DATOS!C32) | C37: =IF(BASE_DE_DATOS!D32="","",BASE_DE_DATOS!D32) | D37: =IF(BASE_DE_DATOS!E32="","",BASE_DE_DATOS!E32) | E37: =IF(BASE_DE_DATOS!G32="","",BASE_DE_DATOS!G32) -> 23849 | F37: =IF(BASE_DE_DATOS!H32="","",BASE_DE_DATOS!H32) | G37: =IF(BASE_DE_DATOS!J32="","",BASE_DE_DATOS!J32) -> 23849 | H37: =IF(BASE_DE_DATOS!N32="","",BASE_DE_DATOS!N32) | J37: 11.7 | K37: =F34 | L37: 23.99 | M37: =K37/J37 -> #VALUE! | N37: =L37*M37 -> #VALUE!
J38: 11.7 | K38: =F35 | L38: 23.99 | M38: =K38/J38 -> #VALUE! | N38: =L38*M38 -> #VALUE!
J39: 11.7 | K39: =F36 | L39: 23.99 | M39: =K39/J39 -> #VALUE! | N39: =L39*M39 -> #VALUE!

Sheet 2_BITACORA_VERSA
A1: Día | B1: Usuario Responsable | C1: Áreas de Adscripción | D1: Tipo de Vehículo | E1: Placas | F1: Oficio | H1: Hora de Salida | I1: Km de Salida | J1: Gasolina de Salida | N1: Hora de Llegada | O1: Km de Llegada | P1: Gasolina de Llegada | T1: Dotación de Gasolina | U1: Firma | V1: No. De Licencia | W1: observaciones
F2: Numero | G2: Fecha | J2: v | K2: 1/4 | L2: 1/2 | M2: 1 | P2: v | Q2: 1/4 | R2: 1/2 | S2: 1
A3: =IF(BASE_DE_DATOS!A2="","",BASE_DE_DATOS!A2) -> 24/06/2026 | B3: =IF(BASE_DE_DATOS!R2="","",BASE_DE_DATOS!R2) -> VÍCTOR LEONARDO OLMEDO GONZALEZ | C3: =IF(BASE_DE_DATOS!S2="","",BASE_DE_DATOS!S2) -> RESIDENCIA NAUCALPAN | D3: =IF(BASE_DE_DATOS!T2="","",BASE_DE_DATOS!T2) -> NISSAN VERSA | E3: =IF(BASE_DE_DATOS!U2="","",BASE_DE_DATOS!U2) -> MGX-543-A | F3: =IF(BASE_DE_DATOS!O2="","",BASE_DE_DATOS!O2) | G3: =IF(BASE_DE_DATOS!P2="","",BASE_DE_DATOS!P2) | H3: =IF(BASE_DE_DATOS!F2="","",BASE_DE_DATOS!F2) -> 09:00 | I3: =IF(BASE_DE_DATOS!G2="","",BASE_DE_DATOS!G2) -> 23379 | J3: =IF(BASE_DE_DATOS!L2="v","X","") | K3: =IF(BASE_DE_DATOS!L2="1/4","X","") -> X | L3: =IF(BASE_DE_DATOS!L2="1/2","X","") | M3: =IF(BASE_DE_DATOS!L2="1","X","") | N3: =IF(BASE_DE_DATOS!I2="","",BASE_DE_DATOS!I2) -> 19:00 | O3: =IF(BASE_DE_DATOS!J2="","",BASE_DE_DATOS!J2) -> 23479 | P3: =IF(BASE_DE_DATOS!M2="v","X","") | Q3: =IF(BASE_DE_DATOS!M2="1/4","X","") -> X | R3: =IF(BASE_DE_DATOS!M2="1/2","X","") | S3: =IF(BASE_DE_DATOS!M2="1","X","") | T3: =IF(BASE_DE_DATOS!N2="","",BASE_DE_DATOS!N2) -> 200 | V3: =IF(BASE_DE_DATOS!V2="","",BASE_DE_DATOS!V2) -> 0101P3402484l | W3: =IF(BASE_DE_DATOS!Q2="","",BASE_DE_DATOS!Q2)
A4: =IF(BASE_DE_DATOS!A3="","",BASE_DE_DATOS!A3) -> 25/06/2026 | B4: =IF(BASE_DE_DATOS!R3="","",BASE_DE_DATOS!R3) -> VÍCTOR LEONARDO OLMEDO GONZALEZ | C4: =IF(BASE_DE_DATOS!S3="","",BASE_DE_DATOS!S3) -> RESIDENCIA NAUCALPAN | D4: =IF(BASE_DE_DATOS!T3="","",BASE_DE_DATOS!T3) -> NISSAN VERSA | E4: =IF(BASE_DE_DATOS!U3="","",BASE_DE_DATOS!U3) -> MGX-543-A | F4: =IF(BASE_DE_DATOS!O3="","",BASE_DE_DATOS!O3) | G4: =IF(BASE_DE_DATOS!P3="","",BASE_DE_DATOS!P3) | H4: =IF(BASE_DE_DATOS!F3="","",BASE_DE_DATOS!F3) -> 09:00 | I4: =IF(BASE_DE_DATOS!G3="","",BASE_DE_DATOS!G3) -> 23479 | J4: =IF(BASE_DE_DATOS!L3="v","X","") | K4: =IF(BASE_DE_DATOS!L3="1/4","X","") | L4: =IF(BASE_DE_DATOS!L3="1/2","X","") -> X | M4: =IF(BASE_DE_DATOS!L3="1","X","") | N4: =IF(BASE_DE_DATOS!I3="","",BASE_DE_DATOS!I3) -> 19:00 | O4: =IF(BASE_DE_DATOS!J3="","",BASE_DE_DATOS!J3) -> 23479 | P4: =IF(BASE_DE_DATOS!M3="v","X","") | Q4: =IF(BASE_DE_DATOS!M3="1/4","X","") -> X | R4: =IF(BASE_DE_DATOS!M3="1/2","X","") | S4: =IF(BASE_DE_DATOS!M3="1","X","") | T4: =IF(BASE_DE_DATOS!N3="","",BASE_DE_DATOS!N3) -> 300 | V4: =IF(BASE_DE_DATOS!V3="","",BASE_DE_DATOS!V3) -> 0101P3402484l | W4: =IF(BASE_DE_DATOS!Q3="","",BASE_DE_DATOS!Q3)
A5: =IF(BASE_DE_DATOS!A4="","",BASE_DE_DATOS!A4) -> 26/06/2026 | B5: =IF(BASE_DE_DATOS!R4="","",BASE_DE_DATOS!R4) -> VÍCTOR LEONARDO OLMEDO GONZALEZ | C5: =IF(BASE_DE_DATOS!S4="","",BASE_DE_DATOS!S4) -> RESIDENCIA NAUCALPAN | D5: =IF(BASE_DE_DATOS!T4="","",BASE_DE_DATOS!T4) -> NISSAN VERSA | E5: =IF(BASE_DE_DATOS!U4="","",BASE_DE_DATOS!U4) -> MGX-543-A | F5: =IF(BASE_DE_DATOS!O4="","",BASE_DE_DATOS!O4) | G5: =IF(BASE_DE_DATOS!P4="","",BASE_DE_DATOS!P4) | H5: =IF(BASE_DE_DATOS!F4="","",BASE_DE_DATOS!F4) -> 09:00 | I5: =IF(BASE_DE_DATOS!G4="","",BASE_DE_DATOS!G4) -> 23479 | J5: =IF(BASE_DE_DATOS!L4="v","X","") | K5: =IF(BASE_DE_DATOS!L4="1/4","X","") -> X | L5: =IF(BASE_DE_DATOS!L4="1/2","X","") | M5: =IF(BASE_DE_DATOS!L4="1","X","") | N5: =IF(BASE_DE_DATOS!I4="","",BASE_DE_DATOS!I4) -> 19:00 | O5: =IF(BASE_DE_DATOS!J4="","",BASE_DE_DATOS!J4) -> 23599 | P5: =IF(BASE_DE_DATOS!M4="v","X","") | Q5: =IF(BASE_DE_DATOS!M4="1/4","X","") -> X | R5: =IF(BASE_DE_DATOS!M4="1/2","X","") | S5: =IF(BASE_DE_DATOS!M4="1","X","") | T5: =IF(BASE_DE_DATOS!N4="","",BASE_DE_DATOS!N4) -> 300 | V5: =IF(BASE_DE_DATOS!V4="","",BASE_DE_DATOS!V4) -> 0101P3402484l | W5: =IF(BASE_DE_DATOS!Q4="","",BASE_DE_DATOS!Q4)
A6: =IF(BASE_DE_DATOS!A5="","",BASE_DE_DATOS!A5) -> 29/06/2026 | B6: =IF(BASE_DE_DATOS!R5="","",BASE_DE_DATOS!R5) -> VÍCTOR LEONARDO OLMEDO GONZALEZ | C6: =IF(BASE_DE_DATOS!S5="","",BASE_DE_DATOS!S5) -> RESIDENCIA NAUCALPAN | D6: =IF(BASE_DE_DATOS!T5="","",BASE_DE_DATOS!T5) -> NISSAN VERSA | E6: =IF(BASE_DE_DATOS!U5="","",BASE_DE_DATOS!U5) -> MGX-543-A | F6: =IF(BASE_DE_DATOS!O5="","",BASE_DE_DATOS!O5) | G6: =IF(BASE_DE_DATOS!P5="","",BASE_DE_DATOS!P5) | H6: =IF(BASE_DE_DATOS!F5="","",BASE_DE_DATOS!F5) -> 09:00 | I6: =IF(BASE_DE_DATOS!G5="","",BASE_DE_DATOS!G5) -> 23599 | J6: =IF(BASE_DE_DATOS!L5="v","X","") | K6: =IF(BASE_DE_DATOS!L5="1/4","X","") -> X | L6: =IF(BASE_DE_DATOS!L5="1/2","X","") | M6: =IF(BASE_DE_DATOS!L5="1","X","") | N6: =IF(BASE_DE_DATOS!I5="","",BASE_DE_DATOS!I5) -> 19:00 | O6: =IF(BASE_DE_DATOS!J5="","",BASE_DE_DATOS!J5) -> 23799 | P6: =IF(BASE_DE_DATOS!M5="v","X","") | Q6: =IF(BASE_DE_DATOS!M5="1/4","X","") -> X | R6: =IF(BASE_DE_DATOS!M5="1/2","X","") | S6: =IF(BASE_DE_DATOS!M5="1","X","") | T6: =IF(BASE_DE_DATOS!N5="","",BASE_DE_DATOS!N5) -> 200 | V6: =IF(BASE_DE_DATOS!V5="","",BASE_DE_DATOS!V5) -> 0101P3402484l | W6: =IF(BASE_DE_DATOS!Q5="","",BASE_DE_DATOS!Q5)
A7: =IF(BASE_DE_DATOS!A6="","",BASE_DE_DATOS!A6) -> 30/06/2026 | B7: =IF(BASE_DE_DATOS!R6="","",BASE_DE_DATOS!R6) -> VÍCTOR LEONARDO OLMEDO GONZALEZ | C7: =IF(BASE_DE_DATOS!S6="","",BASE_DE_DATOS!S6) -> RESIDENCIA NAUCALPAN | D7: =IF(BASE_DE_DATOS!T6="","",BASE_DE_DATOS!T6) -> NISSAN VERSA | E7: =IF(BASE_DE_DATOS!U6="","",BASE_DE_DATOS!U6) -> MGX-543-A | F7: =IF(BASE_DE_DATOS!O6="","",BASE_DE_DATOS!O6) | G7: =IF(BASE_DE_DATOS!P6="","",BASE_DE_DATOS!P6) | H7: =IF(BASE_DE_DATOS!F6="","",BASE_DE_DATOS!F6) -> 09:00 | I7: =IF(BASE_DE_DATOS!G6="","",BASE_DE_DATOS!G6) -> 23799 | J7: =IF(BASE_DE_DATOS!L6="v","X","") | K7: =IF(BASE_DE_DATOS!L6="1/4","X","") -> X | L7: =IF(BASE_DE_DATOS!L6="1/2","X","") | M7: =IF(BASE_DE_DATOS!L6="1","X","") | N7: =IF(BASE_DE_DATOS!I6="","",BASE_DE_DATOS!I6) -> 19:00 | O7: =IF(BASE_DE_DATOS!J6="","",BASE_DE_DATOS!J6) -> 23849 | P7: =IF(BASE_DE_DATOS!M6="v","X","") | Q7: =IF(BASE_DE_DATOS!M6="1/4","X","") -> X | R7: =IF(BASE_DE_DATOS!M6="1/2","X","") | S7: =IF(BASE_DE_DATOS!M6="1","X","") | T7: =IF(BASE_DE_DATOS!N6="","",BASE_DE_DATOS!N6) -> 200 | V7: =IF(BASE_DE_DATOS!V6="","",BASE_DE_DATOS!V6) -> 0101P3402484l | W7: =IF(BASE_DE_DATOS!Q6="","",BASE_DE_DATOS!Q6)
A8: =IF(BASE_DE_DATOS!A7="","",BASE_DE_DATOS!A7) -> 46305 | B8: =IF(BASE_DE_DATOS!R7="","",BASE_DE_DATOS!R7) -> VÍCTOR LEONARDO OLMEDO GONZALEZ | C8: =IF(BASE_DE_DATOS!S7="","",BASE_DE_DATOS!S7) -> RESIDENCIA NAUCALPAN | D8: =IF(BASE_DE_DATOS!T7="","",BASE_DE_DATOS!T7) -> NISSAN VERSA | E8: =IF(BASE_DE_DATOS!U7="","",BASE_DE_DATOS!U7) -> MGX-543-A | F8: =IF(BASE_DE_DATOS!O7="","",BASE_DE_DATOS!O7) | G8: =IF(BASE_DE_DATOS!P7="","",BASE_DE_DATOS!P7) | H8: =IF(BASE_DE_DATOS!F7="","",BASE_DE_DATOS!F7) -> 09:00 | I8: =IF(BASE_DE_DATOS!G7="","",BASE_DE_DATOS!G7) -> 23849 | J8: =IF(BASE_DE_DATOS!L7="v","X","") | K8: =IF(BASE_DE_DATOS!L7="1/4","X","") | L8: =IF(BASE_DE_DATOS!L7="1/2","X","") | M8: =IF(BASE_DE_DATOS!L7="1","X","") | N8: =IF(BASE_DE_DATOS!I7="","",BASE_DE_DATOS!I7) -> 19:00 | O8: =IF(BASE_DE_DATOS!J7="","",BASE_DE_DATOS!J7) -> 23849 | P8: =IF(BASE_DE_DATOS!M7="v","X","") | Q8: =IF(BASE_DE_DATOS!M7="1/4","X","") | R8: =IF(BASE_DE_DATOS!M7="1/2","X","") | S8: =IF(BASE_DE_DATOS!M7="1","X","") | T8: =IF(BASE_DE_DATOS!N7="","",BASE_DE_DATOS!N7) | V8: =IF(BASE_DE_DATOS!V7="","",BASE_DE_DATOS!V7) -> 0101P3402484l | W8: =IF(BASE_DE_DATOS!Q7="","",BASE_DE_DATOS!Q7)
A9: =IF(BASE_DE_DATOS!A8="","",BASE_DE_DATOS!A8) -> 07/07/2026 | B9: =IF(BASE_DE_DATOS!R8="","",BASE_DE_DATOS!R8) -> VÍCTOR LEONARDO OLMEDO GONZALEZ | C9: =IF(BASE_DE_DATOS!S8="","",BASE_DE_DATOS!S8) -> RESIDENCIA NAUCALPAN | D9: =IF(BASE_DE_DATOS!T8="","",BASE_DE_DATOS!T8) -> NISSAN VERSA | E9: =IF(BASE_DE_DATOS!U8="","",BASE_DE_DATOS!U8) -> MGX-543-A | F9: =IF(BASE_DE_DATOS!O8="","",BASE_DE_DATOS!O8) | G9: =IF(BASE_DE_DATOS!P8="","",BASE_DE_DATOS!P8) | H9: =IF(BASE_DE_DATOS!F8="","",BASE_DE_DATOS!F8) -> 09:00 | I9: =IF(BASE_DE_DATOS!G8="","",BASE_DE_DATOS!G8) -> 23849 | J9: =IF(BASE_DE_DATOS!L8="v","X","") | K9: =IF(BASE_DE_DATOS!L8="1/4","X","") | L9: =IF(BASE_DE_DATOS!L8="1/2","X","") | M9: =IF(BASE_DE_DATOS!L8="1","X","") | N9: =IF(BASE_DE_DATOS!I8="","",BASE_DE_DATOS!I8) -> 19:00 | O9: =IF(BASE_DE_DATOS!J8="","",BASE_DE_DATOS!J8) -> 23849 | P9: =IF(BASE_DE_DATOS!M8="v","X","") | Q9: =IF(BASE_DE_DATOS!M8="1/4","X","") | R9: =IF(BASE_DE_DATOS!M8="1/2","X","") | S9: =IF(BASE_DE_DATOS!M8="1","X","") | T9: =IF(BASE_DE_DATOS!N8="","",BASE_DE_DATOS!N8) | V9: =IF(BASE_DE_DATOS!V8="","",BASE_DE_DATOS!V8) -> 0101P3402484l | W9: =IF(BASE_DE_DATOS!Q8="","",BASE_DE_DATOS!Q8)
A10: =IF(BASE_DE_DATOS!A9="","",BASE_DE_DATOS!A9) -> 08/07/2026 | B10: =IF(BASE_DE_DATOS!R9="","",BASE_DE_DATOS!R9) -> VÍCTOR LEONARDO OLMEDO GONZALEZ | C10: =IF(BASE_DE_DATOS!S9="","",BASE_DE_DATOS!S9) -> RESIDENCIA NAUCALPAN | D10: =IF(BASE_DE_DATOS!T9="","",BASE_DE_DATOS!T9) -> NISSAN VERSA | E10: =IF(BASE_DE_DATOS!U9="","",BASE_DE_DATOS!U9) -> MGX-543-A | F10: =IF(BASE_DE_DATOS!O9="","",BASE_DE_DATOS!O9) | G10: =IF(BASE_DE_DATOS!P9="","",BASE_DE_DATOS!P9) | H10: =IF(BASE_DE_DATOS!F9="","",BASE_DE_DATOS!F9) -> 09:00 | I10: =IF(BASE_DE_DATOS!G9="","",BASE_DE_DATOS!G9) -> 23849 | J10: =IF(BASE_DE_DATOS!L9="v","X","") | K10: =IF(BASE_DE_DATOS!L9="1/4","X","") | L10: =IF(BASE_DE_DATOS!L9="1/2","X","") | M10: =IF(BASE_DE_DATOS!L9="1","X","") | N10: =IF(BASE_DE_DATOS!I9="","",BASE_DE_DATOS!I9) -> 19:00 | O10: =IF(BASE_DE_DATOS!J9="","",BASE_DE_DATOS!J9) -> 23849 | P10: =IF(BASE_DE_DATOS!M9="v","X","") | Q10: =IF(BASE_DE_DATOS!M9="1/4","X","") | R10: =IF(BASE_DE_DATOS!M9="1/2","X","") | S10: =IF(BASE_DE_DATOS!M9="1","X","") | T10: =IF(BASE_DE_DATOS!N9="","",BASE_DE_DATOS!N9) | V10: =IF(BASE_DE_DATOS!V9="","",BASE_DE_DATOS!V9) -> 0101P3402484l | W10: =IF(BASE_DE_DATOS!Q9="","",BASE_DE_DATOS!Q9)
A11: =IF(BASE_DE_DATOS!A10="","",BASE_DE_DATOS!A10) -> 09/07/2026 | B11: =IF(BASE_DE_DATOS!R10="","",BASE_DE_DATOS!R10) -> VÍCTOR LEONARDO OLMEDO GONZALEZ | C11: =IF(BASE_DE_DATOS!S10="","",BASE_DE_DATOS!S10) -> RESIDENCIA NAUCALPAN | D11: =IF(BASE_DE_DATOS!T10="","",BASE_DE_DATOS!T10) -> NISSAN VERSA | E11: =IF(BASE_DE_DATOS!U10="","",BASE_DE_DATOS!U10) -> MGX-543-A | F11: =IF(BASE_DE_DATOS!O10="","",BASE_DE_DATOS!O10) | G11: =IF(BASE_DE_DATOS!P10="","",BASE_DE_DATOS!P10) | H11: =IF(BASE_DE_DATOS!F10="","",BASE_DE_DATOS!F10) -> 09:00 | I11: =IF(BASE_DE_DATOS!G10="","",BASE_DE_DATOS!G10) -> 23849 | J11: =IF(BASE_DE_DATOS!L10="v","X","") | K11: =IF(BASE_DE_DATOS!L10="1/4","X","") | L11: =IF(BASE_DE_DATOS!L10="1/2","X","") | M11: =IF(BASE_DE_DATOS!L10="1","X","") | N11: =IF(BASE_DE_DATOS!I10="","",BASE_DE_DATOS!I10) -> 19:00 | O11: =IF(BASE_DE_DATOS!J10="","",BASE_DE_DATOS!J10) -> 23849 | P11: =IF(BASE_DE_DATOS!M10="v","X","") | Q11: =IF(BASE_DE_DATOS!M10="1/4","X","") | R11: =IF(BASE_DE_DATOS!M10="1/2","X","") | S11: =IF(BASE_DE_DATOS!M10="1","X","") | T11: =IF(BASE_DE_DATOS!N10="","",BASE_DE_DATOS!N10) | V11: =IF(BASE_DE_DATOS!V10="","",BASE_DE_DATOS!V10) -> 0101P3402484l | W11: =IF(BASE_DE_DATOS!Q10="","",BASE_DE_DATOS!Q10)
A12: =IF(BASE_DE_DATOS!A11="","",BASE_DE_DATOS!A11) -> 10/07/2026 | B12: =IF(BASE_DE_DATOS!R11="","",BASE_DE_DATOS!R11) -> VÍCTOR LEONARDO OLMEDO GONZALEZ | C12: =IF(BASE_DE_DATOS!S11="","",BASE_DE_DATOS!S11) -> RESIDENCIA NAUCALPAN | D12: =IF(BASE_DE_DATOS!T11="","",BASE_DE_DATOS!T11) -> NISSAN VERSA | E12: =IF(BASE_DE_DATOS!U11="","",BASE_DE_DATOS!U11) -> MGX-543-A | F12: =IF(BASE_DE_DATOS!O11="","",BASE_DE_DATOS!O11) | G12: =IF(BASE_DE_DATOS!P11="","",BASE_DE_DATOS!P11) | H12: =IF(BASE_DE_DATOS!F11="","",BASE_DE_DATOS!F11) -> 09:00 | I12: =IF(BASE_DE_DATOS!G11="","",BASE_DE_DATOS!G11) -> 23849 | J12: =IF(BASE_DE_DATOS!L11="v","X","") | K12: =IF(BASE_DE_DATOS!L11="1/4","X","") | L12: =IF(BASE_DE_DATOS!L11="1/2","X","") | M12: =IF(BASE_DE_DATOS!L11="1","X","") | N12: =IF(BASE_DE_DATOS!I11="","",BASE_DE_DATOS!I11) -> 19:00 | O12: =IF(BASE_DE_DATOS!J11="","",BASE_DE_DATOS!J11) -> 23849 | P12: =IF(BASE_DE_DATOS!M11="v","X","") | Q12: =IF(BASE_DE_DATOS!M11="1/4","X","") | R12: =IF(BASE_DE_DATOS!M11="1/2","X","") | S12: =IF(BASE_DE_DATOS!M11="1","X","") | T12: =IF(BASE_DE_DATOS!N11="","",BASE_DE_DATOS!N11) | V12: =IF(BASE_DE_DATOS!V11="","",BASE_DE_DATOS!V11) -> 0101P3402484l | W12: =IF(BASE_DE_DATOS!Q11="","",BASE_DE_DATOS!Q11)
A13: =IF(BASE_DE_DATOS!A12="","",BASE_DE_DATOS!A12) -> 11/07/2026 | B13: =IF(BASE_DE_DATOS!R12="","",BASE_DE_DATOS!R12) -> VÍCTOR LEONARDO OLMEDO GONZALEZ | C13: =IF(BASE_DE_DATOS!S12="","",BASE_DE_DATOS!S12) -> RESIDENCIA NAUCALPAN | D13: =IF(BASE_DE_DATOS!T12="","",BASE_DE_DATOS!T12) -> NISSAN VERSA | E13: =IF(BASE_DE_DATOS!U12="","",BASE_DE_DATOS!U12) -> MGX-543-A | F13: =IF(BASE_DE_DATOS!O12="","",BASE_DE_DATOS!O12) | G13: =IF(BASE_DE_DATOS!P12="","",BASE_DE_DATOS!P12) | H13: =IF(BASE_DE_DATOS!F12="","",BASE_DE_DATOS!F12) -> 09:00 | I13: =IF(BASE_DE_DATOS!G12="","",BASE_DE_DATOS!G12) -> 23849 | J13: =IF(BASE_DE_DATOS!L12="v","X","") | K13: =IF(BASE_DE_DATOS!L12="1/4","X","") | L13: =IF(BASE_DE_DATOS!L12="1/2","X","") | M13: =IF(BASE_DE_DATOS!L12="1","X","") | N13: =IF(BASE_DE_DATOS!I12="","",BASE_DE_DATOS!I12) -> 19:00 | O13: =IF(BASE_DE_DATOS!J12="","",BASE_DE_DATOS!J12) -> 23849 | P13: =IF(BASE_DE_DATOS!M12="v","X","") | Q13: =IF(BASE_DE_DATOS!M12="1/4","X","") | R13: =IF(BASE_DE_DATOS!M12="1/2","X","") | S13: =IF(BASE_DE_DATOS!M12="1","X","") | T13: =IF(BASE_DE_DATOS!N12="","",BASE_DE_DATOS!N12) | V13: =IF(BASE_DE_DATOS!V12="","",BASE_DE_DATOS!V12) -> 0101P3402484l | W13: =IF(BASE_DE_DATOS!Q12="","",BASE_DE_DATOS!Q12)
A14: =IF(BASE_DE_DATOS!A13="","",BASE_DE_DATOS!A13) -> 12/07/2026 | B14: =IF(BASE_DE_DATOS!R13="","",BASE_DE_DATOS!R13) -> VÍCTOR LEONARDO OLMEDO GONZALEZ | C14: =IF(BASE_DE_DATOS!S13="","",BASE_DE_DATOS!S13) -> RESIDENCIA NAUCALPAN | D14: =IF(BASE_DE_DATOS!T13="","",BASE_DE_DATOS!T13) -> NISSAN VERSA | E14: =IF(BASE_DE_DATOS!U13="","",BASE_DE_DATOS!U13) -> MGX-543-A | F14: =IF(BASE_DE_DATOS!O13="","",BASE_DE_DATOS!O13) | G14: =IF(BASE_DE_DATOS!P13="","",BASE_DE_DATOS!P13) | H14: =IF(BASE_DE_DATOS!F13="","",BASE_DE_DATOS!F13) -> 09:00 | I14: =IF(BASE_DE_DATOS!G13="","",BASE_DE_DATOS!G13) -> 23849 | J14: =IF(BASE_DE_DATOS!L13="v","X","") | K14: =IF(BASE_DE_DATOS!L13="1/4","X","") | L14: =IF(BASE_DE_DATOS!L13="1/2","X","") | M14: =IF(BASE_DE_DATOS!L13="1","X","") | N14: =IF(BASE_DE_DATOS!I13="","",BASE_DE_DATOS!I13) -> 19:00 | O14: =IF(BASE_DE_DATOS!J13="","",BASE_DE_DATOS!J13) -> 23849 | P14: =IF(BASE_DE_DATOS!M13="v","X","") | Q14: =IF(BASE_DE_DATOS!M13="1/4","X","") | R14: =IF(BASE_DE_DATOS!M13="1/2","X","") | S14: =IF(BASE_DE_DATOS!M13="1","X","") | T14: =IF(BASE_DE_DATOS!N13="","",BASE_DE_DATOS!N13) | V14: =IF(BASE_DE_DATOS!V13="","",BASE_DE_DATOS!V13) -> 0101P3402484l | W14: =IF(BASE_DE_DATOS!Q13="","",BASE_DE_DATOS!Q13)
... A33: =IF(BASE_DE_DATOS!A32="","",BASE_DE_DATOS!A32) -> 31/07/2026 | B33: =IF(BASE_DE_DATOS!R32="","",BASE_DE_DATOS!R32) -> VÍCTOR LEONARDO OLMEDO GONZALEZ | C33: =IF(BASE_DE_DATOS!S32="","",BASE_DE_DATOS!S32) -> RESIDENCIA NAUCALPAN | D33: =IF(BASE_DE_DATOS!T32="","",BASE_DE_DATOS!T32) -> NISSAN VERSA | E33: =IF(BASE_DE_DATOS!U32="","",BASE_DE_DATOS!U32) -> MGX-543-A | F33: =IF(BASE_DE_DATOS!O32="","",BASE_DE_DATOS!O32) | G33: =IF(BASE_DE_DATOS!P32="","",BASE_DE_DATOS!P32) | H33: =IF(BASE_DE_DATOS!F32="","",BASE_DE_DATOS!F32) -> 09:00 | I33: =IF(BASE_DE_DATOS!G32="","",BASE_DE_DATOS!G32) -> 23849 | J33: =IF(BASE_DE_DATOS!L32="v","X","") | K33: =IF(BASE_DE_DATOS!L32="1/4","X","") | L33: =IF(BASE_DE_DATOS!L32="1/2","X","") | M33: =IF(BASE_DE_DATOS!L32="1","X","") | N33: =IF(BASE_DE_DATOS!I32="","",BASE_DE_DATOS!I32) -> 19:00 | O33: =IF(BASE_DE_DATOS!J32="","",BASE_DE_DATOS!J32) -> 23849 | P33: =IF(BASE_DE_DATOS!M32="v","X","") | Q33: =IF(BASE_DE_DATOS!M32="1/4","X","") | R33: =IF(BASE_DE_DATOS!M32="1/2","X","") | S33: =IF(BASE_DE_DATOS!M32="1","X","") | T33: =IF(BASE_DE_DATOS!N32="","",BASE_DE_DATOS!N32) | V33: =IF(BASE_DE_DATOS!V32="","",BASE_DE_DATOS!V32) -> 0101P3402484l | W33: =IF(BASE_DE_DATOS!Q32="","",BASE_DE_DATOS!Q32)

Sheet 3_BITACORAS_INDIVIDUALES
A1: ="BITÁCORA " & VLOOKUP(D2, BASE_DE_DATOS!$A$2:$B$100, 2, FALSE) -> BITÁCORA JUNIO
A2: ÁREA: | B2: RESIDENCIA NAUCALPAN | C2: FECHA: | D2: =IF(BASE_DE_DATOS!A2="","",BASE_DE_DATOS!A2) -> 24/06/2026
A3: TIPO DE VEHICULO: | B3: =IF(BASE_DE_DATOS!T2="","",BASE_DE_DATOS!T2) -> NISSAN VERSA | C3: PLACAS: | D3: =IF(BASE_DE_DATOS!U2="","",BASE_DE_DATOS!U2) -> MGX-543-A
A4: USUARIO: | B4: =IF(BASE_DE_DATOS!R2="","",BASE_DE_DATOS!R2) -> VÍCTOR LEONARDO OLMEDO GONZALEZ | C4: No. LICENCIA: | D4: =IF(BASE_DE_DATOS!V2="","",BASE_DE_DATOS!V2) -> 0101P3402484l
A5: HORA DE SALIDA: | B5: =IF(BASE_DE_DATOS!F2="","",BASE_DE_DATOS!F2) -> 09:00 | C5: OFICIO: | D5: =IF(BASE_DE_DATOS!O2="","",BASE_DE_DATOS!O2)
A6: GASOLINA: | B6: V ¼ ½ 1/1 | C6: KM DE SALIDA: | D6: =IF(BASE_DE_DATOS!G2="","",BASE_DE_DATOS!G2) -> 23379
A7: HORA DE LLEGADA: | B7: =IF(BASE_DE_DATOS!I2="","",BASE_DE_DATOS!I2) -> 19:00 | C7: KM DE LLEGADA: | D7: =IF(BASE_DE_DATOS!J2="","",BASE_DE_DATOS!J2) -> 23479
A8: GASOLINA: | B8: V ¼ ½ 1/1 | C8: =IF(BASE_DE_DATOS!N2="","",BASE_DE_DATOS!N2) -> 200
A9: DOTACIÓN DE VALES: | B9: =IF(BASE_DE_DATOS!C2="","",BASE_DE_DATOS!C2) -> TOLUCA | C9: TICKET DE CARGA GASOLINA:
A10: OBSERVACIONES: | B10: =IF(BASE_DE_DATOS!D2="","",BASE_DE_DATOS!D2) -> ZINACANTEPEC-(REPRESENTACIÓN)PENSIÓN
A13: ="BITÁCORA " & VLOOKUP(D14, BASE_DE_DATOS!$A$2:$B$100, 2, FALSE) -> BITÁCORA JUNIO
A14: ÁREA: | B14: RESIDENCIA NAUCALPAN | C14: FECHA: | D14: =IF(BASE_DE_DATOS!A3="","",BASE_DE_DATOS!A3) -> 25/06/2026
A15: TIPO DE VEHICULO: | B15: =IF(BASE_DE_DATOS!T3="","",BASE_DE_DATOS!T3) -> NISSAN VERSA | C15: PLACAS: | D15: =IF(BASE_DE_DATOS!U3="","",BASE_DE_DATOS!U3) -> MGX-543-A
A16: USUARIO: | B16: =IF(BASE_DE_DATOS!R3="","",BASE_DE_DATOS!R3) -> VÍCTOR LEONARDO OLMEDO GONZALEZ | C16: No. LICENCIA: | D16: =IF(BASE_DE_DATOS!V3="","",BASE_DE_DATOS!V3) -> 0101P3402484l
A17: HORA DE SALIDA: | B17: =IF(BASE_DE_DATOS!F3="","",BASE_DE_DATOS!F3) -> 09:00 | C17: OFICIO: | D17: =IF(BASE_DE_DATOS!O3="","",BASE_DE_DATOS!O3)
A18: GASOLINA: | B18: V ¼ ½ 1/1 | C18: KM DE SALIDA: | D18: =IF(BASE_DE_DATOS!G3="","",BASE_DE_DATOS!G3) -> 23479
A19: HORA DE LLEGADA: | B19: =IF(BASE_DE_DATOS!I3="","",BASE_DE_DATOS!I3) -> 19:00 | C19: KM DE LLEGADA: | D19: =IF(BASE_DE_DATOS!J3="","",BASE_DE_DATOS!J3) -> 23479
A20: GASOLINA: | B20: V ¼ ½ 1/1 | C20: =IF(BASE_DE_DATOS!N3="","",BASE_DE_DATOS!N3) -> 300
A21: DOTACIÓN DE VALES: | B21: =IF(BASE_DE_DATOS!C3="","",BASE_DE_DATOS!C3) -> HUEHUETOCA | C21: TICKET DE CARGA GASOLINA:
A22: OBSERVACIONES: | B22: =IF(BASE_DE_DATOS!D3="","",BASE_DE_DATOS!D3) -> HUEHUETOCA - SANTIAGO TLALTEPOXCO
A25: ="BITÁCORA " & VLOOKUP(D26, BASE_DE_DATOS!$A$2:$B$100, 2, FALSE) -> BITÁCORA JUNIO
A26: ÁREA: | B26: RESIDENCIA NAUCALPAN | C26: FECHA: | D26: =IF(BASE_DE_DATOS!A4="","",BASE_DE_DATOS!A4) -> 26/06/2026
A27: TIPO DE VEHICULO: | B27: =IF(BASE_DE_DATOS!T4="","",BASE_DE_DATOS!T4) -> NISSAN VERSA | C27: PLACAS: | D27: =IF(BASE_DE_DATOS!U4="","",BASE_DE_DATOS!U4) -> MGX-543-A
A28: USUARIO: | B28: =IF(BASE_DE_DATOS!R4="","",BASE_DE_DATOS!R4) -> VÍCTOR LEONARDO OLMEDO GONZALEZ | C28: No. LICENCIA: | D28: =IF(BASE_DE_DATOS!V4="","",BASE_DE_DATOS!V4) -> 0101P3402484l
A29: HORA DE SALIDA: | B29: =IF(BASE_DE_DATOS!F4="","",BASE_DE_DATOS!F4) -> 09:00 | C29: OFICIO: | D29: =IF(BASE_DE_DATOS!O4="","",BASE_DE_DATOS!O4)
A30: GASOLINA: | B30: V ¼ ½ 1/1 | C30: KM DE SALIDA: | D30: =IF(BASE_DE_DATOS!G4="","",BASE_DE_DATOS!G4) -> 23479
A31: HORA DE LLEGADA: | B31: =IF(BASE_DE_DATOS!I4="","",BASE_DE_DATOS!I4) -> 19:00 | C31: KM DE LLEGADA: | D31: =IF(BASE_DE_DATOS!J4="","",BASE_DE_DATOS!J4) -> 23599
A32: GASOLINA: | B32: V ¼ ½ 1/1 | C32: =IF(BASE_DE_DATOS!N4="","",BASE_DE_DATOS!N4) -> 300
A33: DOTACIÓN DE VALES: | B33: =IF(BASE_DE_DATOS!C4="","",BASE_DE_DATOS!C4) -> TULTITLAN-NICOLAS ROMERO | C33: TICKET DE CARGA GASOLINA:
A34: OBSERVACIONES: | B34: =IF(BASE_DE_DATOS!D4="","",BASE_DE_DATOS!D4) -> SAN FRANCISCO MAGÚ
A37: ="BITÁCORA " & VLOOKUP(D38, BASE_DE_DATOS!$A$2:$B$100, 2, FALSE) -> BITÁCORA JUNIO
A38: ÁREA: | B38: RESIDENCIA NAUCALPAN | C38: FECHA: | D38: =IF(BASE_DE_DATOS!A5="","",BASE_DE_DATOS!A5) -> 29/06/2026
A39: TIPO DE VEHICULO: | B39: =IF(BASE_DE_DATOS!T5="","",BASE_DE_DATOS!T5) -> NISSAN VERSA | C39: PLACAS: | D39: =IF(BASE_DE_DATOS!U5="","",BASE_DE_DATOS!U5) -> MGX-543-A
A40: USUARIO: | B40: =IF(BASE_DE_DATOS!R5="","",BASE_DE_DATOS!R5) -> VÍCTOR LEONARDO OLMEDO GONZALEZ | C40: No. LICENCIA: | D40: =IF(BASE_DE_DATOS!V5="","",BASE_DE_DATOS!V5) -> 0101P3402484l
A41: HORA DE SALIDA: | B41: =IF(BASE_DE_DATOS!F5="","",BASE_DE_DATOS!F5) -> 09:00 | C41: OFICIO: | D41: =IF(BASE_DE_DATOS!O5="","",BASE_DE_DATOS!O5)
A42: GASOLINA: | B42: V ¼ ½ 1/1 | C42: KM DE SALIDA: | D42: =IF(BASE_DE_DATOS!G5="","",BASE_DE_DATOS!G5) -> 23599
A43: HORA DE LLEGADA: | B43: =IF(BASE_DE_DATOS!I5="","",BASE_DE_DATOS!I5) -> 19:00 | C43: KM DE LLEGADA: | D43: =IF(BASE_DE_DATOS!J5="","",BASE_DE_DATOS!J5) -> 23799
A44: GASOLINA: | B44: V ¼ ½ 1/1 | C44: =IF(BASE_DE_DATOS!N5="","",BASE_DE_DATOS!N5) -> 200
A45: DOTACIÓN DE VALES: | B45: =IF(BASE_DE_DATOS!C5="","",BASE_DE_DATOS!C5) -> TOLUCA | C45: TICKET DE CARGA GASOLINA:
A46: OBSERVACIONES: | B46: =IF(BASE_DE_DATOS!D5="","",BASE_DE_DATOS!D5) -> ZINACANTEPEC-(REPRESENTACIÓN)PENSIÓN
...
